<?xml version="1.0" encoding="UTF-8"?>
<testng-results ignored="0" total="4" passed="1" failed="2" skipped="1">
  <reporter-output>
  </reporter-output>
  <suite started-at="2023-11-20T10:44:23 PST" name="Suite" finished-at="2023-11-20T10:44:24 PST" duration-ms="1140">
    <groups>
    </groups>
    <test started-at="2023-11-20T10:44:23 PST" name="Test1" finished-at="2023-11-20T10:44:23 PST" duration-ms="55">
      <class name="listeners.TestClass">
        <test-method signature="testMethod1()[pri:0, instance:listeners.TestClass@72f926e6]" started-at="2023-11-20T10:44:23 PST" name="testMethod1" finished-at="2023-11-20T10:44:23 PST" duration-ms="12" status="PASS">
          <reporter-output>
          </reporter-output>
        </test-method> <!-- testMethod1 -->
        <test-method signature="testMethod2()[pri:0, instance:listeners.TestClass@72f926e6]" started-at="2023-11-20T10:44:23 PST" name="testMethod2" finished-at="2023-11-20T10:44:23 PST" duration-ms="2" status="FAIL">
          <exception class="java.lang.AssertionError">
            <full-stacktrace>
              <![CDATA[java.lang.AssertionError: 
at org.testng.AssertJUnit.fail(AssertJUnit.java:65)
at org.testng.AssertJUnit.assertTrue(AssertJUnit.java:23)
at org.testng.AssertJUnit.assertTrue(AssertJUnit.java:33)
at listeners.TestClass.testMethod2(TestClass.java:23)
at java.base/jdk.internal.reflect.DirectMethodHandleAccessor.invoke(DirectMethodHandleAccessor.java:104)
at java.base/java.lang.reflect.Method.invoke(Method.java:578)
at org.testng.internal.invokers.MethodInvocationHelper.invokeMethod(MethodInvocationHelper.java:139)
at org.testng.internal.invokers.TestInvoker.invokeMethod(TestInvoker.java:664)
at org.testng.internal.invokers.TestInvoker.invokeTestMethod(TestInvoker.java:227)
at org.testng.internal.invokers.MethodRunner.runInSequence(MethodRunner.java:50)
at org.testng.internal.invokers.TestInvoker$MethodInvocationAgent.invoke(TestInvoker.java:957)
at org.testng.internal.invokers.TestInvoker.invokeTestMethods(TestInvoker.java:200)
at org.testng.internal.invokers.TestMethodWorker.invokeTestMethods(TestMethodWorker.java:148)
at org.testng.internal.invokers.TestMethodWorker.run(TestMethodWorker.java:128)
at java.base/java.util.ArrayList.forEach(ArrayList.java:1511)
at org.testng.TestRunner.privateRun(TestRunner.java:848)
at org.testng.TestRunner.run(TestRunner.java:621)
at org.testng.SuiteRunner.runTest(SuiteRunner.java:443)
at org.testng.SuiteRunner.runSequentially(SuiteRunner.java:437)
at org.testng.SuiteRunner.privateRun(SuiteRunner.java:397)
at org.testng.SuiteRunner.run(SuiteRunner.java:336)
at org.testng.SuiteRunnerWorker.runSuite(SuiteRunnerWorker.java:52)
at org.testng.SuiteRunnerWorker.run(SuiteRunnerWorker.java:95)
at org.testng.TestNG.runSuitesSequentially(TestNG.java:1280)
at org.testng.TestNG.runSuitesLocally(TestNG.java:1200)
at org.testng.TestNG.runSuites(TestNG.java:1114)
at org.testng.TestNG.run(TestNG.java:1082)
at org.testng.remote.AbstractRemoteTestNG.run(AbstractRemoteTestNG.java:115)
at org.testng.remote.RemoteTestNG.initAndRun(RemoteTestNG.java:251)
at org.testng.remote.RemoteTestNG.main(RemoteTestNG.java:77)
]]>
            </full-stacktrace>
          </exception> <!-- java.lang.AssertionError -->
          <reporter-output>
          </reporter-output>
        </test-method> <!-- testMethod2 -->
      </class> <!-- listeners.TestClass -->
    </test> <!-- Test1 -->
    <test started-at="2023-11-20T10:44:23 PST" name="Test2" finished-at="2023-11-20T10:44:24 PST" duration-ms="1021">
      <class name="listeners.TestClass">
        <test-method signature="testMethod3()[pri:0, instance:listeners.TestClass@9f116cc]" started-at="2023-11-20T10:44:23 PST" name="testMethod3" finished-at="2023-11-20T10:44:24 PST" duration-ms="1006" status="FAIL">
          <exception class="org.testng.internal.thread.ThreadTimeoutException">
            <message>
              <![CDATA[Method listeners.TestClass.testMethod3() didn't finish within the time-out 1000]]>
            </message>
            <full-stacktrace>
              <![CDATA[org.testng.internal.thread.ThreadTimeoutException: Method listeners.TestClass.testMethod3() didn't finish within the time-out 1000
at java.base/java.lang.Thread.sleep0(Native Method)
at java.base/java.lang.Thread.sleep(Thread.java:484)
at listeners.TestClass.testMethod3(TestClass.java:28)
at java.base/jdk.internal.reflect.DirectMethodHandleAccessor.invoke(DirectMethodHandleAccessor.java:104)
at java.base/java.lang.reflect.Method.invoke(Method.java:578)
at org.testng.internal.invokers.MethodInvocationHelper.invokeMethod(MethodInvocationHelper.java:139)
at org.testng.internal.invokers.InvokeMethodRunnable.runOne(InvokeMethodRunnable.java:47)
at org.testng.internal.invokers.InvokeMethodRunnable.call(InvokeMethodRunnable.java:76)
at org.testng.internal.invokers.InvokeMethodRunnable.call(InvokeMethodRunnable.java:11)
at java.base/java.util.concurrent.FutureTask.run(FutureTask.java:317)
at java.base/java.util.concurrent.ThreadPoolExecutor.runWorker(ThreadPoolExecutor.java:1144)
at java.base/java.util.concurrent.ThreadPoolExecutor$Worker.run(ThreadPoolExecutor.java:642)
at java.base/java.lang.Thread.run(Thread.java:1623)
]]>
            </full-stacktrace>
          </exception> <!-- org.testng.internal.thread.ThreadTimeoutException -->
          <reporter-output>
          </reporter-output>
        </test-method> <!-- testMethod3 -->
        <test-method signature="testMethod4()[pri:0, instance:listeners.TestClass@9f116cc]" started-at="2023-11-20T10:44:24 PST" name="testMethod4" finished-at="2023-11-20T10:44:24 PST" depends-on-methods="listeners.TestClass.testMethod3" duration-ms="0" status="SKIP">
          <exception class="java.lang.Throwable">
            <message>
              <![CDATA[Method listeners.TestClass.testMethod4() on instance listeners.TestClass@9f116cc depends on not successfully finished methods 
[listeners.TestClass.testMethod3() on instance listeners.TestClass@9f116cc]]]>
            </message>
            <full-stacktrace>
              <![CDATA[java.lang.Throwable: Method listeners.TestClass.testMethod4() on instance listeners.TestClass@9f116cc depends on not successfully finished methods 
[listeners.TestClass.testMethod3() on instance listeners.TestClass@9f116cc]
at org.testng.internal.invokers.TestInvoker.invokeTestMethods(TestInvoker.java:156)
at org.testng.internal.invokers.TestMethodWorker.invokeTestMethods(TestMethodWorker.java:148)
at org.testng.internal.invokers.TestMethodWorker.run(TestMethodWorker.java:128)
at java.base/java.util.ArrayList.forEach(ArrayList.java:1511)
at org.testng.TestRunner.privateRun(TestRunner.java:848)
at org.testng.TestRunner.run(TestRunner.java:621)
at org.testng.SuiteRunner.runTest(SuiteRunner.java:443)
at org.testng.SuiteRunner.runSequentially(SuiteRunner.java:437)
at org.testng.SuiteRunner.privateRun(SuiteRunner.java:397)
at org.testng.SuiteRunner.run(SuiteRunner.java:336)
at org.testng.SuiteRunnerWorker.runSuite(SuiteRunnerWorker.java:52)
at org.testng.SuiteRunnerWorker.run(SuiteRunnerWorker.java:95)
at org.testng.TestNG.runSuitesSequentially(TestNG.java:1280)
at org.testng.TestNG.runSuitesLocally(TestNG.java:1200)
at org.testng.TestNG.runSuites(TestNG.java:1114)
at org.testng.TestNG.run(TestNG.java:1082)
at org.testng.remote.AbstractRemoteTestNG.run(AbstractRemoteTestNG.java:115)
at org.testng.remote.RemoteTestNG.initAndRun(RemoteTestNG.java:251)
at org.testng.remote.RemoteTestNG.main(RemoteTestNG.java:77)
]]>
            </full-stacktrace>
          </exception> <!-- java.lang.Throwable -->
          <reporter-output>
          </reporter-output>
        </test-method> <!-- testMethod4 -->
      </class> <!-- listeners.TestClass -->
    </test> <!-- Test2 -->
  </suite> <!-- Suite -->
</testng-results>
